Workbook

Sheet PokemonList
A1: Number | B1: Grade | C1: Pokémon | D1: Type | E1: Version
A2: 1-1-001 | B2: 6-star | C2: Mewtwo | D2: Psychic | E2: Stardust V1
A3: 1-1-002 | B3: 6-star | C3: Mew | D3: Psychic | E3: Stardust V1
A4: 1-1-003 | B4: 6-star | C4: Zacian | D4: Fairy/Steel | E4: Stardust V1
A5: 1-1-004 | B5: 6-star | C5: Zamazenta | D5: Fight/Steel | E5: Stardust V1
A6: 1-1-005 | B6: 6-star | C6: Tyranitar | D6: Rock/Dark | E6: Stardust V1
A7: 1-1-006 | B7: 6-star | C7: Metagross | D7: Steel/Psychic | E7: Stardust V1
A8: 1-1-007 | B8: 6-star | C8: Miraidon | D8: Elec/Dragon | E8: Stardust V1
A9: 1-1-008 | B9: 6-star | C9: Venusaur | D9: Grass/Poison | E9: Stardust V1
A10: 1-1-009 | B10: 6-star | C10: Charizard | D10: Fire/Flying | E10: Stardust V1
A11: 1-1-010 | B11: 6-star | C11: Blastoise | D11: Water | E11: Stardust V1
A12: 1-1-011 | B12: 5-star | C12: Vaporeon | D12: Water | E12: Stardust V1
... A144: R-1-3 | B144: Special | C144: Pikachu | D144: Electric | E144: Special

Sheet WeaknessChart
A1: Pokémon | B1: Type | C1: ½× Resists | D1: ¼× | E1: 0× Immune
A2: Mewtwo | B2: Psychic | C2: Fighting, Psychic | D2: – | E2: –
A3: Mew | B3: Psychic | C3: Fighting, Psychic | D3: – | E3: –
A4: Zacian | B4: Fairy | C4: Fighting, Bug, Dark | D4: – | E4: Dragon
A5: Zamazenta | B5: Fighting | C5: Rock, Bug, Dark | D5: – | E5: –
A6: Tyranitar | B6: Rock/Dark | C6: Normal, Flying, Poison, Fire, Dark | D6: – | E6: Psychic
A7: Metagross | B7: Steel/Psychic | C7: Normal, Flying, Rock, Grass, Ice, Dragon, Steel, Fairy | D7: Psychic | E7: Poison
A8: Miraidon | B8: Electric/Dragon | C8: Fire, Water, Grass, Electric, Flying, Steel | D8: – | E8: –
A9: Venusaur | B9: Grass/Poison | C9: Water, Electric, Fighting, Fairy | D9: Grass | E9: –
A10: Charizard | B10: Fire/Flying | C10: Fire, Fighting, Steel, Fairy | D10: Grass | E10: Ground
A11: Blastoise | B11: Water | C11: Fire, Water, Ice, Steel | D11: – | E11: –
A12: Vaporeon | B12: Water | C12: Fire, Water, Ice, Steel | D12: – | E12: –
... A133: Lucario | B133: Fighting/Steel | C133: Normal, Grass, Ice, Rock, Dark, Steel | D133: – | E133: Poison

Sheet Stars
A1: Tag ID | B1: Pokémon | C1: Star Rarity
A2: 1-2-001 | B2: Kyogre | C2: 6-star
A3: 1-2-002 | B3: Groudon | C3: 6-star
A4: 1-2-003 | B4: Koraidon | C4: 6-star
A5: 1-2-004 | B5: Pikachu | C5: 6-star
A6: 1-2-005 | B6: Snorlax | C6: 6-star
A7: 1-2-006 | B7: Kommo-o | C7: 6-star
A8: 1-2-007 | B8: Gardevoir | C8: 6-star
A9: 1-2-008 | B9: Reshiram | C9: 6-star
A10: 1-2-009 | B10: Zekrom | C10: 6-star
A11: 1-2-010 | B11: Kyurem | C11: 6-star
A12: 1-2-011 | B12: Jolteon | C12: 5-star
... A144: R-1-3 | B144: Snorlax | C144: Special

Sheet Move_List
A1: Move Name | B1: Type | C1: Damage Class | D1: Power | E1: Accuracy | F1: PP | G1: Effect
A2: Pound | B2: Normal | C2: Physical | D2: 40 | E2: 100 | F2: 35 | G2: Inflicts regular damage with no additional effect.
A3: Karate Chop | B3: Fighting | C3: Physical | D3: 50 | E3: 100 | F3: 25 | G3: Has an increased chance for a critical hit.
A4: Double Slap | B4: Normal | C4: Physical | D4: 15 | E4: 85 | F4: 10 | G4: Hits 2-5 times in one turn.
A5: Comet Punch | B5: Normal | C5: Physical | D5: 18 | E5: 85 | F5: 15 | G5: Hits 2-5 times in one turn.
A6: Mega Punch | B6: Normal | C6: Physical | D6: 80 | E6: 85 | F6: 20 | G6: Inflicts regular damage with no additional effect.
A7: Pay Day | B7: Normal | C7: Physical | D7: 40 | E7: 100 | F7: 20 | G7: Scatters money on the ground worth five times the user’s level.
A8: Fire Punch | B8: Fire | C8: Physical | D8: 75 | E8: 100 | F8: 15 | G8: Has a $effect_chance% chance to burn the target.
A9: Ice Punch | B9: Ice | C9: Physical | D9: 75 | E9: 100 | F9: 15 | G9: Has a $effect_chance% chance to freeze the target.
A10: Thunder Punch | B10: Electric | C10: Physical | D10: 75 | E10: 100 | F10: 15 | G10: Has a $effect_chance% chance to paralyze the target.
A11: Scratch | B11: Normal | C11: Physical | D11: 40 | E11: 100 | F11: 35 | G11: Inflicts regular damage with no additional effect.
A12: Vice Grip | B12: Normal | C12: Physical | D12: 55 | E12: 100 | F12: 30 | G12: Inflicts regular damage with no additional effect.
A13: Guillotine | B13: Normal | C13: Physical | E13: 30 | F13: 5 | G13: Causes a one-hit KO.
A14: Razor Wind | B14: Normal | C14: Special | D14: 80 | E14: 100 | F14: 10 | G14: Requires a turn to charge before attacking.
A15: Swords Dance | B15: Normal | C15: Status | F15: 20 | G15: Raises the user’s Attack by two stages.
A16: Cut | B16: Normal | C16: Physical | D16: 50 | E16: 95 | F16: 30 | G16: Inflicts regular damage with no additional effect.
A17: Gust | B17: Flying | C17: Special | D17: 40 | E17: 100 | F17: 35 | G17: Inflicts regular damage and can hit Pokémon in the air.
A18: Wing Attack | B18: Flying | C18: Physical | D18: 60 | E18: 100 | F18: 35 | G18: Inflicts regular damage with no additional effect.
A19: Whirlwind | B19: Normal | C19: Status | F19: 20 | G19: Immediately ends wild battles. Forces trainers to switch Pokémon.
A20: Fly | B20: Flying | C20: Physical | D20: 90 | E20: 95 | F20: 15 | G20: User flies high into the air, dodging all attacks, and hits next turn.
A21: Bind | B21: Normal | C21: Physical | D21: 15 | E21: 85 | F21: 20 | G21: Prevents the target from fleeing and inflicts damage for 2-5 turns.
A22: Slam | B22: Normal | C22: Physical | D22: 80 | E22: 75 | F22: 20 | G22: Inflicts regular damage with no additional effect.
A23: Vine Whip | B23: Grass | C23: Physical | D23: 45 | E23: 100 | F23: 25 | G23: Inflicts regular damage with no additional effect.
A24: Stomp | B24: Normal | C24: Physical | D24: 65 | E24: 100 | F24: 20 | G24: Has a $effect_chance% chance to make the target flinch.
A25: Double Kick | B25: Fighting | C25: Physical | D25: 30 | E25: 100 | F25: 30 | G25: Hits twice in one turn.
A26: Mega Kick | B26: Normal | C26: Physical | D26: 120 | E26: 75 | F26: 5 | G26: Inflicts regular damage with no additional effect.
A27: Jump Kick | B27: Fighting | C27: Physical | D27: 100 | E27: 95 | F27: 10 | G27: If the user misses, it takes half the damage it would have inflicted in recoil.
A28: Rolling Kick | B28: Fighting | C28: Physical | D28: 60 | E28: 85 | F28: 15 | G28: Has a $effect_chance% chance to make the target flinch.
A29: Sand Attack | B29: Ground | C29: Status | E29: 100 | F29: 15 | G29: Lowers the target’s accuracy by one stage.
A30: Headbutt | B30: Normal | C30: Physical | D30: 70 | E30: 100 | F30: 15 | G30: Has a $effect_chance% chance to make the target flinch.
A31: Horn Attack | B31: Normal | C31: Physical | D31: 65 | E31: 100 | F31: 25 | G31: Inflicts regular damage with no additional effect.
A32: Fury Attack | B32: Normal | C32: Physical | D32: 15 | E32: 85 | F32: 20 | G32: Hits 2-5 times in one turn.
A33: Horn Drill | B33: Normal | C33: Physical | E33: 30 | F33: 5 | G33: Causes a one-hit KO.
A34: Tackle | B34: Normal | C34: Physical | D34: 40 | E34: 100 | F34: 35 | G34: Inflicts regular damage with no additional effect.
A35: Body Slam | B35: Normal | C35: Physical | D35: 85 | E35: 100 | F35: 15 | G35: Has a $effect_chance% chance to paralyze the target.
A36: Wrap | B36: Normal | C36: Physical | D36: 15 | E36: 90 | F36: 20 | G36: Prevents the target from fleeing and inflicts damage for 2-5 turns.
A37: Take Down | B37: Normal | C37: Physical | D37: 90 | E37: 85 | F37: 20 | G37: User receives 1/4 the damage it inflicts in recoil.
A38: Thrash | B38: Normal | C38: Physical | D38: 120 | E38: 100 | F38: 10 | G38: Hits every turn for 2-3 turns, then confuses the user.
A39: Double Edge | B39: Normal | C39: Physical | D39: 120 | E39: 100 | F39: 15 | G39: User receives 1/3 the damage inflicted in recoil.
A40: Tail Whip | B40: Normal | C40: Status | E40: 100 | F40: 30 | G40: Lowers the target’s Defense by one stage.
...

Sheet MoveList_OLD
A1: Move Name | B1: Type | C1: Category | D1: Adjusted Power
A2: Inferno Overdrive | B2: Fire | C2: Z-Move | D2: 200
A3: Tectonic Rage | B3: Ground | C3: Z-Move | D3: 200
A4: Gigavolt Havoc | B4: Electric | C4: Z-Move | D4: 200
A5: All-Out Pummeling | B5: Fighting | C5: Z-Move | D5: 200
A6: Corkscrew Crash | B6: Steel | C6: Z-Move | D6: 200
A7: Max Rockfall | B7: Rock | C7: Dynamax | D7: 160
A8: Max Steelspike | B8: Steel | C8: Dynamax | D8: 160
A9: Max Lightning | B9: Electric | C9: Dynamax | D9: 160
A10: Max Quake | B10: Ground | C10: Dynamax | D10: 160
A11: Max Strike | B11: Normal | C11: Dynamax | D11: 160
A12: Max Knuckle | B12: Fighting | C12: Dynamax | D12: 140
A13: Electro Drift | B13: Electric | C13: Special | D13: 130
... A104: Teleport | B104: Psychic | C104: Status | D104: 0

Sheet Main_Table
A1: Number | B1: Pokemon | C1: Star | D1: Normal/Special Move | E1: Gimmick Move | F1: Move Accuracy | G1: PE | H1: SPD | I1: Sp.A | J1: Sp.D | K1: ATK | L1: DEF | M1: HP | N1: Normal Damage | O1: Gimmick Move Damage | P1: Survivability | Q1: Hunt Power | R1: PE Efficiency
A2: 1-2-005 | B2: Snorlax | C2: =_xlfn.XLOOKUP(A2,Stars!A:A,Stars!C:C) -> 6-star | D2: Giga Impact | E2: Max Strike | F2: 1 | G2: 144 | H2: 39 | I2: 80 | J2: 132 | K2: 132 | L2: 80 | M2: 253 | N2: {=IFERROR(_xlfn.XLOOKUP(D2, Move_List!$A:$A, Move_List!$D:$D) * _xlfn.IFS(UPPER(TRIM(_xlfn.XLOOKUP(D2, Move_List!$A:$A, Move_List!$C:$C)))="PHYSICAL", K2, UPPER(TRIM(_xlfn.XLOOKUP(D2, Move_List!$A:$A, Move_List!$C:$C)))="SPECIAL", I2, TRUE, 0), 0)} -> 19800 | O2: {=IFERROR( _xlfn.XLOOKUP(D2, Move_List!$A:$A, Move_List!$D:$D) * _xlfn.IFS( ISNUMBER(SEARCH("Max", E2)), LOOKUP(_xlfn.XLOOKUP(D2, Move_List!$A:$A, Move_List!$D:$D), {0,60,80,110,150}, {2.5,1.83,1.63,1.27,1}), E2<>"", LOOKUP(_xlfn.XLOOKUP(D2, Move_List!$A:$A, Move_List!$D:$D), {0,60,80,90,100,110,120,150}, {2.5,2,2,1.94,1.8,1.68,1.58,1.33}), TRUE, 0 ) * IF(_xlfn.XLOOKUP(D2, Move_List!$A:$A, Move_List!$C:$C)="Physical", K2, I2), 0)} -> 19800 | P2: =(J2 + L2 + M2) / 3 -> 155 | Q2: =IF(O2>0, (N2+O2)/2, N2) * (P2 / 100) -> 30690 | R2: {=IFERROR(Q2 / IF(OR(_xlfn.IFNA(_xlfn.XLOOKUP(E2, Move_List!$A:$A, Move_List!$C:$C), "")={"Dynamax","Mega"}), G2*1.2, G2), 0)} -> 213.125
A3: 1-1-005 | B3: Tyranitar | C3: =_xlfn.XLOOKUP(A3,Stars!A:A,Stars!C:C) -> 6-star | D3: Stone Edge | E3: Max Rockfall | F3: 1 | G3: 144 | H3: 69 | I3: 105 | J3: 111 | K3: 147 | L3: 121 | M3: 169 | N3: {=IFERROR(_xlfn.XLOOKUP(D3, Move_List!$A:$A, Move_List!$D:$D) * _xlfn.IFS(UPPER(TRIM(_xlfn.XLOOKUP(D3, Move_List!$A:$A, Move_List!$C:$C)))="PHYSICAL", K3, UPPER(TRIM(_xlfn.XLOOKUP(D3, Move_List!$A:$A, Move_List!$C:$C)))="SPECIAL", I3, TRUE, 0), 0)} -> 14700 | O3: {=IFERROR( _xlfn.XLOOKUP(D3, Move_List!$A:$A, Move_List!$D:$D) * _xlfn.IFS( ISNUMBER(SEARCH("Max", E3)), LOOKUP(_xlfn.XLOOKUP(D3, Move_List!$A:$A, Move_List!$D:$D), {0,60,80,110,150}, {2.5,1.83,1.63,1.27,1}), E3<>"", LOOKUP(_xlfn.XLOOKUP(D3, Move_List!$A:$A, Move_List!$D:$D), {0,60,80,90,100,110,120,150}, {2.5,2,2,1.94,1.8,1.68,1.58,1.33}), TRUE, 0 ) * IF(_xlfn.XLOOKUP(D3, Move_List!$A:$A, Move_List!$C:$C)="Physical", K3, I3), 0)} -> 23961 | P3: =(J3 + L3 + M3) / 3 -> 133.66667 | Q3: =IF(O3>0, (N3+O3)/2, N3) * (P3 / 100) -> 25838.435 | R3: {=IFERROR(Q3 / IF(OR(_xlfn.IFNA(_xlfn.XLOOKUP(E3, Move_List!$A:$A, Move_List!$C:$C), "")={"Dynamax","Mega"}), G3*1.2, G3), 0)} -> 179.43358
A4: 1-2-002 | B4: Groudon | C4: =_xlfn.XLOOKUP(A4,Stars!A:A,Stars!C:C) -> 6-star | D4: Precipice Blades | F4: 0.85 | G4: 152 | H4: 95 | I4: 105 | J4: 95 | K4: 155 | L4: 145 | M4: 160 | N4: {=IFERROR(_xlfn.XLOOKUP(D4, Move_List!$A:$A, Move_List!$D:$D) * _xlfn.IFS(UPPER(TRIM(_xlfn.XLOOKUP(D4, Move_List!$A:$A, Move_List!$C:$C)))="PHYSICAL", K4, UPPER(TRIM(_xlfn.XLOOKUP(D4, Move_List!$A:$A, Move_List!$C:$C)))="SPECIAL", I4, TRUE, 0), 0)} -> 18600 | O4: {=IFERROR( _xlfn.XLOOKUP(D4, Move_List!$A:$A, Move_List!$D:$D) * _xlfn.IFS( ISNUMBER(SEARCH("Max", E4)), LOOKUP(_xlfn.XLOOKUP(D4, Move_List!$A:$A, Move_List!$D:$D), {0,60,80,110,150}, {2.5,1.83,1.63,1.27,1}), E4<>"", LOOKUP(_xlfn.XLOOKUP(D4, Move_List!$A:$A, Move_List!$D:$D), {0,60,80,90,100,110,120,150}, {2.5,2,2,1.94,1.8,1.68,1.58,1.33}), TRUE, 0 ) * IF(_xlfn.XLOOKUP(D4, Move_List!$A:$A, Move_List!$C:$C)="Physical", K4, I4), 0)} -> 0 | P4: =(J4 + L4 + M4) / 3 -> 133.33333 | Q4: =IF(O4>0, (N4+O4)/2, N4) * (P4 / 100) -> 24800 | R4: {=IFERROR(Q4 / IF(OR(_xlfn.IFNA(_xlfn.XLOOKUP(E4, Move_List!$A:$A, Move_List!$C:$C), "")={"Dynamax","Mega"}), G4*1.2, G4), 0)} -> 163.15789
A5: 1-1-006 | B5: Metagross | C5: =_xlfn.XLOOKUP(A5,Stars!A:A,Stars!C:C) -> 6-star | D5: Meteor Mash | E5: Max Steelspike | F5: 1 | G5: 144 | H5: 79 | I5: 105 | J5: 100 | K5: 148 | L5: 142 | M5: 147 | N5: {=IFERROR(_xlfn.XLOOKUP(D5, Move_List!$A:$A, Move_List!$D:$D) * _xlfn.IFS(UPPER(TRIM(_xlfn.XLOOKUP(D5, Move_List!$A:$A, Move_List!$C:$C)))="PHYSICAL", K5, UPPER(TRIM(_xlfn.XLOOKUP(D5, Move_List!$A:$A, Move_List!$C:$C)))="SPECIAL", I5, TRUE, 0), 0)} -> 13320 | O5: {=IFERROR( _xlfn.XLOOKUP(D5, Move_List!$A:$A, Move_List!$D:$D) * _xlfn.IFS( ISNUMBER(SEARCH("Max", E5)), LOOKUP(_xlfn.XLOOKUP(D5, Move_List!$A:$A, Move_List!$D:$D), {0,60,80,110,150}, {2.5,1.83,1.63,1.27,1}), E5<>"", LOOKUP(_xlfn.XLOOKUP(D5, Move_List!$A:$A, Move_List!$D:$D), {0,60,80,90,100,110,120,150}, {2.5,2,2,1.94,1.8,1.68,1.58,1.33}), TRUE, 0 ) * IF(_xlfn.XLOOKUP(D5, Move_List!$A:$A, Move_List!$C:$C)="Physical", K5, I5), 0)} -> 21711.6 | P5: =(J5 + L5 + M5) / 3 -> 129.66667 | Q5: =IF(O5>0, (N5+O5)/2, N5) * (P5 / 100) -> 22712.154 | R5: {=IFERROR(Q5 / IF(OR(_xlfn.IFNA(_xlfn.XLOOKUP(E5, Move_List!$A:$A, Move_List!$C:$C), "")={"Dynamax","Mega"}), G5*1.2, G5), 0)} -> 157.72329
A6: 1-2-006 | B6: Kommo-o | C6: =_xlfn.XLOOKUP(A6,Stars!A:A,Stars!C:C) -> 6-star | D6: Focus Blast | E6: Max Knuckle | F6: 1 | G6: 158 | H6: 103 | I6: 121 | J6: 126 | K6: 132 | L6: 150 | M6: 155 | N6: {=IFERROR(_xlfn.XLOOKUP(D6, Move_List!$A:$A, Move_List!$D:$D) * _xlfn.IFS(UPPER(TRIM(_xlfn.XLOOKUP(D6, Move_List!$A:$A, Move_List!$C:$C)))="PHYSICAL", K6, UPPER(TRIM(_xlfn.XLOOKUP(D6, Move_List!$A:$A, Move_List!$C:$C)))="SPECIAL", I6, TRUE, 0), 0)} -> 14520 | O6: {=IFERROR( _xlfn.XLOOKUP(D6, Move_List!$A:$A, Move_List!$D:$D) * _xlfn.IFS( ISNUMBER(SEARCH("Max", E6)), LOOKUP(_xlfn.XLOOKUP(D6, Move_List!$A:$A, Move_List!$D:$D), {0,60,80,110,150}, {2.5,1.83,1.63,1.27,1}), E6<>"", LOOKUP(_xlfn.XLOOKUP(D6, Move_List!$A:$A, Move_List!$D:$D), {0,60,80,90,100,110,120,150}, {2.5,2,2,1.94,1.8,1.68,1.58,1.33}), TRUE, 0 ) * IF(_xlfn.XLOOKUP(D6, Move_List!$A:$A, Move_List!$C:$C)="Physical", K6, I6), 0)} -> 18440.4 | P6: =(J6 + L6 + M6) / 3 -> 143.66667 | Q6: =IF(O6>0, (N6+O6)/2, N6) * (P6 / 100) -> 23676.554 | R6: {=IFERROR(Q6 / IF(OR(_xlfn.IFNA(_xlfn.XLOOKUP(E6, Move_List!$A:$A, Move_List!$C:$C), "")={"Dynamax","Mega"}), G6*1.2, G6), 0)} -> 149.85161
A7: R-1-3 | B7: Snorlax | C7: =_xlfn.XLOOKUP(A7,Stars!A:A,Stars!C:C) -> Special | D7: Giga Impact | E7: Max Strike | F7: 1 | G7: 104 | H7: 29 | I7: 58 | J7: 95 | K7: 95 | L7: 58 | M7: 182 | N7: {=IFERROR(_xlfn.XLOOKUP(D7, Move_List!$A:$A, Move_List!$D:$D) * _xlfn.IFS(UPPER(TRIM(_xlfn.XLOOKUP(D7, Move_List!$A:$A, Move_List!$C:$C)))="PHYSICAL", K7, UPPER(TRIM(_xlfn.XLOOKUP(D7, Move_List!$A:$A, Move_List!$C:$C)))="SPECIAL", I7, TRUE, 0), 0)} -> 14250 | O7: {=IFERROR( _xlfn.XLOOKUP(D7, Move_List!$A:$A, Move_List!$D:$D) * _xlfn.IFS( ISNUMBER(SEARCH("Max", E7)), LOOKUP(_xlfn.XLOOKUP(D7, Move_List!$A:$A, Move_List!$D:$D), {0,60,80,110,150}, {2.5,1.83,1.63,1.27,1}), E7<>"", LOOKUP(_xlfn.XLOOKUP(D7, Move_List!$A:$A, Move_List!$D:$D), {0,60,80,90,100,110,120,150}, {2.5,2,2,1.94,1.8,1.68,1.58,1.33}), TRUE, 0 ) * IF(_xlfn.XLOOKUP(D7, Move_List!$A:$A, Move_List!$C:$C)="Physical", K7, I7), 0)} -> 14250 | P7: =(J7 + L7 + M7) / 3 -> 111.66667 | Q7: =IF(O7>0, (N7+O7)/2, N7) * (P7 / 100) -> 15912.5 | R7: {=IFERROR(Q7 / IF(OR(_xlfn.IFNA(_xlfn.XLOOKUP(E7, Move_List!$A:$A, Move_List!$C:$C), "")={"Dynamax","Mega"}), G7*1.2, G7), 0)} -> 153.00481
A8: 1-2-001 | B8: Kyogre | C8: =_xlfn.XLOOKUP(A8,Stars!A:A,Stars!C:C) -> 6-star | D8: Origin Pulse | F8: 0.85 | G8: 152 | H8: 95 | I8: 155 | J8: 145 | K8: 105 | L8: 95 | M8: 160 | N8: {=IFERROR(_xlfn.XLOOKUP(D8, Move_List!$A:$A, Move_List!$D:$D) * _xlfn.IFS(UPPER(TRIM(_xlfn.XLOOKUP(D8, Move_List!$A:$A, Move_List!$C:$C)))="PHYSICAL", K8, UPPER(TRIM(_xlfn.XLOOKUP(D8, Move_List!$A:$A, Move_List!$C:$C)))="SPECIAL", I8, TRUE, 0), 0)} -> 17050 | O8: {=IFERROR( _xlfn.XLOOKUP(D8, Move_List!$A:$A, Move_List!$D:$D) * _xlfn.IFS( ISNUMBER(SEARCH("Max", E8)), LOOKUP(_xlfn.XLOOKUP(D8, Move_List!$A:$A, Move_List!$D:$D), {0,60,80,110,150}, {2.5,1.83,1.63,1.27,1}), E8<>"", LOOKUP(_xlfn.XLOOKUP(D8, Move_List!$A:$A, Move_List!$D:$D), {0,60,80,90,100,110,120,150}, {2.5,2,2,1.94,1.8,1.68,1.58,1.33}), TRUE, 0 ) * IF(_xlfn.XLOOKUP(D8, Move_List!$A:$A, Move_List!$C:$C)="Physical", K8, I8), 0)} -> 0 | P8: =(J8 + L8 + M8) / 3 -> 133.33333 | Q8: =IF(O8>0, (N8+O8)/2, N8) * (P8 / 100) -> 22733.333 | R8: {=IFERROR(Q8 / IF(OR(_xlfn.IFNA(_xlfn.XLOOKUP(E8, Move_List!$A:$A, Move_List!$C:$C), "")={"Dynamax","Mega"}), G8*1.2, G8), 0)} -> 149.5614
A9: 1-2-021 | B9: Metagross | C9: =_xlfn.XLOOKUP(A9,Stars!A:A,Stars!C:C) -> 5-star | D9: Meteor Mash | E9: Max Steelspike | F9: 1 | G9: 132 | H9: 72 | I9: 96 | J9: 91 | K9: 134 | L9: 129 | M9: 134 | N9: {=IFERROR(_xlfn.XLOOKUP(D9, Move_List!$A:$A, Move_List!$D:$D) * _xlfn.IFS(UPPER(TRIM(_xlfn.XLOOKUP(D9, Move_List!$A:$A, Move_List!$C:$C)))="PHYSICAL", K9, UPPER(TRIM(_xlfn.XLOOKUP(D9, Move_List!$A:$A, Move_List!$C:$C)))="SPECIAL", I9, TRUE, 0), 0)} -> 12060 | O9: {=IFERROR( _xlfn.XLOOKUP(D9, Move_List!$A:$A, Move_List!$D:$D) * _xlfn.IFS( ISNUMBER(SEARCH("Max", E9)), LOOKUP(_xlfn.XLOOKUP(D9, Move_List!$A:$A, Move_List!$D:$D), {0,60,80,110,150}, {2.5,1.83,1.63,1.27,1}), E9<>"", LOOKUP(_xlfn.XLOOKUP(D9, Move_List!$A:$A, Move_List!$D:$D), {0,60,80,90,100,110,120,150}, {2.5,2,2,1.94,1.8,1.68,1.58,1.33}), TRUE, 0 ) * IF(_xlfn.XLOOKUP(D9, Move_List!$A:$A, Move_List!$C:$C)="Physical", K9, I9), 0)} -> 19657.8 | P9: =(J9 + L9 + M9) / 3 -> 118 | Q9: =IF(O9>0, (N9+O9)/2, N9) * (P9 / 100) -> 18713.502 | R9: {=IFERROR(Q9 / IF(OR(_xlfn.IFNA(_xlfn.XLOOKUP(E9, Move_List!$A:$A, Move_List!$C:$C), "")={"Dynamax","Mega"}), G9*1.2, G9), 0)} -> 141.76895
A10: 1-2-009 | B10: Zekrom | C10: =_xlfn.XLOOKUP(A10,Stars!A:A,Stars!C:C) -> 6-star | D10: Fusion Bolt | F10: 1 | G10: 162 | H10: 100 | I10: 132 | J10: 111 | K10: 164 | L10: 132 | M10: 169 | N10: {=IFERROR(_xlfn.XLOOKUP(D10, Move_List!$A:$A, Move_List!$D:$D) * _xlfn.IFS(UPPER(TRIM(_xlfn.XLOOKUP(D10, Move_List!$A:$A, Move_List!$C:$C)))="PHYSICAL", K10, UPPER(TRIM(_xlfn.XLOOKUP(D10, Move_List!$A:$A, Move_List!$C:$C)))="SPECIAL", I10, TRUE, 0), 0)} -> 16400 | O10: {=IFERROR( _xlfn.XLOOKUP(D10, Move_List!$A:$A, Move_List!$D:$D) * _xlfn.IFS( ISNUMBER(SEARCH("Max", E10)), LOOKUP(_xlfn.XLOOKUP(D10, Move_List!$A:$A, Move_List!$D:$D), {0,60,80,110,150}, {2.5,1.83,1.63,1.27,1}), E10<>"", LOOKUP(_xlfn.XLOOKUP(D10, Move_List!$A:$A, Move_List!$D:$D), {0,60,80,90,100,110,120,150}, {2.5,2,2,1.94,1.8,1.68,1.58,1.33}), TRUE, 0 ) * IF(_xlfn.XLOOKUP(D10, Move_List!$A:$A, Move_List!$C:$C)="Physical", K10, I10), 0)} -> 0 | P10: =(J10 + L10 + M10) / 3 -> 137.33333 | Q10: =IF(O10>0, (N10+O10)/2, N10) * (P10 / 100) -> 22522.667 | R10: {=IFERROR(Q10 / IF(OR(_xlfn.IFNA(_xlfn.XLOOKUP(E10, Move_List!$A:$A, Move_List!$C:$C), "")={"Dynamax","Mega"}), G10*1.2, G10), 0)} -> 139.02881
A11: 1-1-003 | B11: Zacian | C11: =_xlfn.XLOOKUP(A11,Stars!A:A,Stars!C:C) -> 6-star | D11: Behemoth Blade | F11: 1 | G11: 162 | H11: 153 | I11: 85 | J11: 120 | K11: 172 | L11: 120 | M11: 152 | N11: {=IFERROR(_xlfn.XLOOKUP(D11, Move_List!$A:$A, Move_List!$D:$D) * _xlfn.IFS(UPPER(TRIM(_xlfn.XLOOKUP(D11, Move_List!$A:$A, Move_List!$C:$C)))="PHYSICAL", K11, UPPER(TRIM(_xlfn.XLOOKUP(D11, Move_List!$A:$A, Move_List!$C:$C)))="SPECIAL", I11, TRUE, 0), 0)} -> 17200 | O11: {=IFERROR( _xlfn.XLOOKUP(D11, Move_List!$A:$A, Move_List!$D:$D) * _xlfn.IFS( ISNUMBER(SEARCH("Max", E11)), LOOKUP(_xlfn.XLOOKUP(D11, Move_List!$A:$A, Move_List!$D:$D), {0,60,80,110,150}, {2.5,1.83,1.63,1.27,1}), E11<>"", LOOKUP(_xlfn.XLOOKUP(D11, Move_List!$A:$A, Move_List!$D:$D), {0,60,80,90,100,110,120,150}, {2.5,2,2,1.94,1.8,1.68,1.58,1.33}), TRUE, 0 ) * IF(_xlfn.XLOOKUP(D11, Move_List!$A:$A, Move_List!$C:$C)="Physical", K11, I11), 0)} -> 0 | P11: =(J11 + L11 + M11) / 3 -> 130.66667 | Q11: =IF(O11>0, (N11+O11)/2, N11) * (P11 / 100) -> 22474.667 | R11: {=IFERROR(Q11 / IF(OR(_xlfn.IFNA(_xlfn.XLOOKUP(E11, Move_List!$A:$A, Move_List!$C:$C), "")={"Dynamax","Mega"}), G11*1.2, G11), 0)} -> 138.73251
A12: 1-2-020 | B12: Tyranitar | C12: =_xlfn.XLOOKUP(A12,Stars!A:A,Stars!C:C) -> 5-star | D12: Stone Edge | E12: Max Rockfall | F12: 1 | G12: 132 | H12: 63 | I12: 96 | J12: 101 | K12: 113 | L12: 110 | M12: 154 | N12: {=IFERROR(_xlfn.XLOOKUP(D12, Move_List!$A:$A, Move_List!$D:$D) * _xlfn.IFS(UPPER(TRIM(_xlfn.XLOOKUP(D12, Move_List!$A:$A, Move_List!$C:$C)))="PHYSICAL", K12, UPPER(TRIM(_xlfn.XLOOKUP(D12, Move_List!$A:$A, Move_List!$C:$C)))="SPECIAL", I12, TRUE, 0), 0)} -> 11300 | O12: {=IFERROR( _xlfn.XLOOKUP(D12, Move_List!$A:$A, Move_List!$D:$D) * _xlfn.IFS( ISNUMBER(SEARCH("Max", E12)), LOOKUP(_xlfn.XLOOKUP(D12, Move_List!$A:$A, Move_List!$D:$D), {0,60,80,110,150}, {2.5,1.83,1.63,1.27,1}), E12<>"", LOOKUP(_xlfn.XLOOKUP(D12, Move_List!$A:$A, Move_List!$D:$D), {0,60,80,90,100,110,120,150}, {2.5,2,2,1.94,1.8,1.68,1.58,1.33}), TRUE, 0 ) * IF(_xlfn.XLOOKUP(D12, Move_List!$A:$A, Move_List!$C:$C)="Physical", K12, I12), 0)} -> 18419 | P12: =(J12 + L12 + M12) / 3 -> 121.66667 | Q12: =IF(O12>0, (N12+O12)/2, N12) * (P12 / 100) -> 18079.058 | R12: {=IFERROR(Q12 / IF(OR(_xlfn.IFNA(_xlfn.XLOOKUP(E12, Move_List!$A:$A, Move_List!$C:$C), "")={"Dynamax","Mega"}), G12*1.2, G12), 0)} -> 136.96256
A13: 1-2-010 | B13: Kyurem | C13: =_xlfn.XLOOKUP(A13,Stars!A:A,Stars!C:C) -> 6-star | D13: Blizzard | F13: 0.7 | G13: 156 | H13: 105 | I13: 142 | J13: 100 | K13: 142 | L13: 100 | M13: 195 | N13: {=IFERROR(_xlfn.XLOOKUP(D13, Move_List!$A:$A, Move_List!$D:$D) * _xlfn.IFS(UPPER(TRIM(_xlfn.XLOOKUP(D13, Move_List!$A:$A, Move_List!$C:$C)))="PHYSICAL", K13, UPPER(TRIM(_xlfn.XLOOKUP(D13, Move_List!$A:$A, Move_List!$C:$C)))="SPECIAL", I13, TRUE, 0), 0)} -> 15620 | O13: {=IFERROR( _xlfn.XLOOKUP(D13, Move_List!$A:$A, Move_List!$D:$D) * _xlfn.IFS( ISNUMBER(SEARCH("Max", E13)), LOOKUP(_xlfn.XLOOKUP(D13, Move_List!$A:$A, Move_List!$D:$D), {0,60,80,110,150}, {2.5,1.83,1.63,1.27,1}), E13<>"", LOOKUP(_xlfn.XLOOKUP(D13, Move_List!$A:$A, Move_List!$D:$D), {0,60,80,90,100,110,120,150}, {2.5,2,2,1.94,1.8,1.68,1.58,1.33}), TRUE, 0 ) * IF(_xlfn.XLOOKUP(D13, Move_List!$A:$A, Move_List!$C:$C)="Physical", K13, I13), 0)} -> 0 | P13: =(J13 + L13 + M13) / 3 -> 131.66667 | Q13: =IF(O13>0, (N13+O13)/2, N13) * (P13 / 100) -> 20566.333 | R13: {=IFERROR(Q13 / IF(OR(_xlfn.IFNA(_xlfn.XLOOKUP(E13, Move_List!$A:$A, Move_List!$C:$C), "")={"Dynamax","Mega"}), G13*1.2, G13), 0)} -> 131.83547
A14: 1-1-014 | B14: Glaceon | C14: =_xlfn.XLOOKUP(A14,Stars!A:A,Stars!C:C) -> 5-star | D14: Blizzard | F14: 1 | G14: 114 | H14: 66 | I14: 127 | J14: 94 | K14: 61 | L14: 108 | M14: 118 | N14: {=IFERROR(_xlfn.XLOOKUP(D14, Move_List!$A:$A, Move_List!$D:$D) * _xlfn.IFS(UPPER(TRIM(_xlfn.XLOOKUP(D14, Move_List!$A:$A, Move_List!$C:$C)))="PHYSICAL", K14, UPPER(TRIM(_xlfn.XLOOKUP(D14, Move_List!$A:$A, Move_List!$C:$C)))="SPECIAL", I14, TRUE, 0), 0)} -> 13970 | O14: {=IFERROR( _xlfn.XLOOKUP(D14, Move_List!$A:$A, Move_List!$D:$D) * _xlfn.IFS( ISNUMBER(SEARCH("Max", E14)), LOOKUP(_xlfn.XLOOKUP(D14, Move_List!$A:$A, Move_List!$D:$D), {0,60,80,110,150}, {2.5,1.83,1.63,1.27,1}), E14<>"", LOOKUP(_xlfn.XLOOKUP(D14, Move_List!$A:$A, Move_List!$D:$D), {0,60,80,90,100,110,120,150}, {2.5,2,2,1.94,1.8,1.68,1.58,1.33}), TRUE, 0 ) * IF(_xlfn.XLOOKUP(D14, Move_List!$A:$A, Move_List!$C:$C)="Physical", K14, I14), 0)} -> 0 | P14: =(J14 + L14 + M14) / 3 -> 106.66667 | Q14: =IF(O14>0, (N14+O14)/2, N14) * (P14 / 100) -> 14901.333 | R14: {=IFERROR(Q14 / IF(OR(_xlfn.IFNA(_xlfn.XLOOKUP(E14, Move_List!$A:$A, Move_List!$C:$C), "")={"Dynamax","Mega"}), G14*1.2, G14), 0)} -> 130.71345
A15: 1-1-001 | B15: Mewtwo | C15: =_xlfn.XLOOKUP(A15,Stars!A:A,Stars!C:C) -> 6-star | D15: Psystrike | F15: 1 | G15: 158 | H15: 140 | I15: 165 | J15: 98 | K15: 119 | L15: 98 | M15: 172 | N15: {=IFERROR(_xlfn.XLOOKUP(D15, Move_List!$A:$A, Move_List!$D:$D) * _xlfn.IFS(UPPER(TRIM(_xlfn.XLOOKUP(D15, Move_List!$A:$A, Move_List!$C:$C)))="PHYSICAL", K15, UPPER(TRIM(_xlfn.XLOOKUP(D15, Move_List!$A:$A, Move_List!$C:$C)))="SPECIAL", I15, TRUE, 0), 0)} -> 16500 | O15: {=IFERROR( _xlfn.XLOOKUP(D15, Move_List!$A:$A, Move_List!$D:$D) * _xlfn.IFS( ISNUMBER(SEARCH("Max", E15)), LOOKUP(_xlfn.XLOOKUP(D15, Move_List!$A:$A, Move_List!$D:$D), {0,60,80,110,150}, {2.5,1.83,1.63,1.27,1}), E15<>"", LOOKUP(_xlfn.XLOOKUP(D15, Move_List!$A:$A, Move_List!$D:$D), {0,60,80,90,100,110,120,150}, {2.5,2,2,1.94,1.8,1.68,1.58,1.33}), TRUE, 0 ) * IF(_xlfn.XLOOKUP(D15, Move_List!$A:$A, Move_List!$C:$C)="Physical", K15, I15), 0)} -> 0 | P15: =(J15 + L15 + M15) / 3 -> 122.66667 | Q15: =IF(O15>0, (N15+O15)/2, N15) * (P15 / 100) -> 20240 | R15: {=IFERROR(Q15 / IF(OR(_xlfn.IFNA(_xlfn.XLOOKUP(E15, Move_List!$A:$A, Move_List!$C:$C), "")={"Dynamax","Mega"}), G15*1.2, G15), 0)} -> 128.10127
A16: 1-1-007 | B16: Miraidon | C16: =_xlfn.XLOOKUP(A16,Stars!A:A,Stars!C:C) -> 6-star | D16: Electro Drift | F16: 1 | G16: 162 | H16: 150 | I16: 150 | J16: 129 | K16: 96 | L16: 113 | M16: 172 | N16: {=IFERROR(_xlfn.XLOOKUP(D16, Move_List!$A:$A, Move_List!$D:$D) * _xlfn.IFS(UPPER(TRIM(_xlfn.XLOOKUP(D16, Move_List!$A:$A, Move_List!$C:$C)))="PHYSICAL", K16, UPPER(TRIM(_xlfn.XLOOKUP(D16, Move_List!$A:$A, Move_List!$C:$C)))="SPECIAL", I16, TRUE, 0), 0)} -> 15000 | O16: {=IFERROR( _xlfn.XLOOKUP(D16, Move_List!$A:$A, Move_List!$D:$D) * _xlfn.IFS( ISNUMBER(SEARCH("Max", E16)), LOOKUP(_xlfn.XLOOKUP(D16, Move_List!$A:$A, Move_List!$D:$D), {0,60,80,110,150}, {2.5,1.83,1.63,1.27,1}), E16<>"", LOOKUP(_xlfn.XLOOKUP(D16, Move_List!$A:$A, Move_List!$D:$D), {0,60,80,90,100,110,120,150}, {2.5,2,2,1.94,1.8,1.68,1.58,1.33}), TRUE, 0 ) * IF(_xlfn.XLOOKUP(D16, Move_List!$A:$A, Move_List!$C:$C)="Physical", K16, I16), 0)} -> 0 | P16: =(J16 + L16 + M16) / 3 -> 138 | Q16: =IF(O16>0, (N16+O16)/2, N16) * (P16 / 100) -> 20700 | R16: {=IFERROR(Q16 / IF(OR(_xlfn.IFNA(_xlfn.XLOOKUP(E16, Move_List!$A:$A, Move_List!$C:$C), "")={"Dynamax","Mega"}), G16*1.2, G16), 0)} -> 127.77778
A17: 1-2-003 | B17: Koraidon | C17: =_xlfn.XLOOKUP(A17,Stars!A:A,Stars!C:C) -> 6-star | D17: Collision Course | F17: 1 | G17: 162 | H17: 150 | I17: 96 | J17: 113 | K17: 150 | L17: 129 | M17: 172 | N17: {=IFERROR(_xlfn.XLOOKUP(D17, Move_List!$A:$A, Move_List!$D:$D) * _xlfn.IFS(UPPER(TRIM(_xlfn.XLOOKUP(D17, Move_List!$A:$A, Move_List!$C:$C)))="PHYSICAL", K17, UPPER(TRIM(_xlfn.XLOOKUP(D17, Move_List!$A:$A, Move_List!$C:$C)))="SPECIAL", I17, TRUE, 0), 0)} -> 15000 | O17: {=IFERROR( _xlfn.XLOOKUP(D17, Move_List!$A:$A, Move_List!$D:$D) * _xlfn.IFS( ISNUMBER(SEARCH("Max", E17)), LOOKUP(_xlfn.XLOOKUP(D17, Move_List!$A:$A, Move_List!$D:$D), {0,60,80,110,150}, {2.5,1.83,1.63,1.27,1}), E17<>"", LOOKUP(_xlfn.XLOOKUP(D17, Move_List!$A:$A, Move_List!$D:$D), {0,60,80,90,100,110,120,150}, {2.5,2,2,1.94,1.8,1.68,1.58,1.33}), TRUE, 0 ) * IF(_xlfn.XLOOKUP(D17, Move_List!$A:$A, Move_List!$C:$C)="Physical", K17, I17), 0)} -> 0 | P17: =(J17 + L17 + M17) / 3 -> 138 | Q17: =IF(O17>0, (N17+O17)/2, N17) * (P17 / 100) -> 20700 | R17: {=IFERROR(Q17 / IF(OR(_xlfn.IFNA(_xlfn.XLOOKUP(E17, Move_List!$A:$A, Move_List!$C:$C), "")={"Dynamax","Mega"}), G17*1.2, G17), 0)} -> 127.77778
A18: 1-1-018 | B18: Rhyperior | C18: =_xlfn.XLOOKUP(A18,Stars!A:A,Stars!C:C) -> 5-star | D18: Earthquake | E18: Tectonic Rage | F18: 1 | G18: 110 | H18: 39 | I18: 53 | J18: 53 | K18: 128 | L18: 119 | M18: 155 | N18: {=IFERROR(_xlfn.XLOOKUP(D18, Move_List!$A:$A, Move_List!$D:$D) * _xlfn.IFS(UPPER(TRIM(_xlfn.XLOOKUP(D18, Move_List!$A:$A, Move_List!$C:$C)))="PHYSICAL", K18, UPPER(TRIM(_xlfn.XLOOKUP(D18, Move_List!$A:$A, Move_List!$C:$C)))="SPECIAL", I18, TRUE, 0), 0)} -> 12800 | O18: {=IFERROR( _xlfn.XLOOKUP(D18, Move_List!$A:$A, Move_List!$D:$D) * _xlfn.IFS( ISNUMBER(SEARCH("Max", E18)), LOOKUP(_xlfn.XLOOKUP(D18, Move_List!$A:$A, Move_List!$D:$D), {0,60,80,110,150}, {2.5,1.83,1.63,1.27,1}), E18<>"", LOOKUP(_xlfn.XLOOKUP(D18, Move_List!$A:$A, Move_List!$D:$D), {0,60,80,90,100,110,120,150}, {2.5,2,2,1.94,1.8,1.68,1.58,1.33}), TRUE, 0 ) * IF(_xlfn.XLOOKUP(D18, Move_List!$A:$A, Move_List!$C:$C)="Physical", K18, I18), 0)} -> 23040 | P18: =(J18 + L18 + M18) / 3 -> 109 | Q18: =IF(O18>0, (N18+O18)/2, N18) * (P18 / 100) -> 19532.8 | R18: {=IFERROR(Q18 / IF(OR(_xlfn.IFNA(_xlfn.XLOOKUP(E18, Move_List!$A:$A, Move_List!$C:$C), "")={"Dynamax","Mega"}), G18*1.2, G18), 0)} -> 177.57091
A19: 1-1-004 | B19: Zamazenta | C19: =_xlfn.XLOOKUP(A19,Stars!A:A,Stars!C:C) -> 6-star | D19: Behemoth Bash | F19: 1 | G19: 162 | H19: 133 | I19: 85 | J19: 150 | K19: 135 | L19: 150 | M19: 152 | N19: {=IFERROR(_xlfn.XLOOKUP(D19, Move_List!$A:$A, Move_List!$D:$D) * _xlfn.IFS(UPPER(TRIM(_xlfn.XLOOKUP(D19, Move_List!$A:$A, Move_List!$C:$C)))="PHYSICAL", K19, UPPER(TRIM(_xlfn.XLOOKUP(D19, Move_List!$A:$A, Move_List!$C:$C)))="SPECIAL", I19, TRUE, 0), 0)} -> 13500 | O19: {=IFERROR( _xlfn.XLOOKUP(D19, Move_List!$A:$A, Move_List!$D:$D) * _xlfn.IFS( ISNUMBER(SEARCH("Max", E19)), LOOKUP(_xlfn.XLOOKUP(D19, Move_List!$A:$A, Move_List!$D:$D), {0,60,80,110,150}, {2.5,1.83,1.63,1.27,1}), E19<>"", LOOKUP(_xlfn.XLOOKUP(D19, Move_List!$A:$A, Move_List!$D:$D), {0,60,80,90,100,110,120,150}, {2.5,2,2,1.94,1.8,1.68,1.58,1.33}), TRUE, 0 ) * IF(_xlfn.XLOOKUP(D19, Move_List!$A:$A, Move_List!$C:$C)="Physical", K19, I19), 0)} -> 0 | P19: =(J19 + L19 + M19) / 3 -> 150.66667 | Q19: =IF(O19>0, (N19+O19)/2, N19) * (P19 / 100) -> 20340 | R19: {=IFERROR(Q19 / IF(OR(_xlfn.IFNA(_xlfn.XLOOKUP(E19, Move_List!$A:$A, Move_List!$C:$C), "")={"Dynamax","Mega"}), G19*1.2, G19), 0)} -> 125.55556
A20: 1-1-008 | B20: Venusaur | C20: =_xlfn.XLOOKUP(A20,Stars!A:A,Stars!C:C) -> 6-star | D20: Leaf Storm | F20: 0.9 | G20: 122 | H20: 85 | I20: 105 | J20: 105 | K20: 87 | L20: 88 | M20: 140 | N20: {=IFERROR(_xlfn.XLOOKUP(D20, Move_List!$A:$A, Move_List!$D:$D) * _xlfn.IFS(UPPER(TRIM(_xlfn.XLOOKUP(D20, Move_List!$A:$A, Move_List!$C:$C)))="PHYSICAL", K20, UPPER(TRIM(_xlfn.XLOOKUP(D20, Move_List!$A:$A, Move_List!$C:$C)))="SPECIAL", I20, TRUE, 0), 0)} -> 13650 | O20: {=IFERROR( _xlfn.XLOOKUP(D20, Move_List!$A:$A, Move_List!$D:$D) * _xlfn.IFS( ISNUMBER(SEARCH("Max", E20)), LOOKUP(_xlfn.XLOOKUP(D20, Move_List!$A:$A, Move_List!$D:$D), {0,60,80,110,150}, {2.5,1.83,1.63,1.27,1}), E20<>"", LOOKUP(_xlfn.XLOOKUP(D20, Move_List!$A:$A, Move_List!$D:$D), {0,60,80,90,100,110,120,150}, {2.5,2,2,1.94,1.8,1.68,1.58,1.33}), TRUE, 0 ) * IF(_xlfn.XLOOKUP(D20, Move_List!$A:$A, Move_List!$C:$C)="Physical", K20, I20), 0)} -> 0 | P20: =(J20 + L20 + M20) / 3 -> 111 | Q20: =IF(O20>0, (N20+O20)/2, N20) * (P20 / 100) -> 15151.5 | R20: {=IFERROR(Q20 / IF(OR(_xlfn.IFNA(_xlfn.XLOOKUP(E20, Move_List!$A:$A, Move_List!$C:$C), "")={"Dynamax","Mega"}), G20*1.2, G20), 0)} -> 124.19262
A21: 1-1-020 | B21: Flygon | C21: =_xlfn.XLOOKUP(A21,Stars!A:A,Stars!C:C) -> 5-star | D21: Earthquake | E21: Max Quake | F21: 1 | G21: 114 | H21: 99 | I21: 80 | J21: 80 | K21: 99 | L21: 80 | M21: 132 | N21: {=IFERROR(_xlfn.XLOOKUP(D21, Move_List!$A:$A, Move_List!$D:$D) * _xlfn.IFS(UPPER(TRIM(_xlfn.XLOOKUP(D21, Move_List!$A:$A, Move_List!$C:$C)))="PHYSICAL", K21, UPPER(TRIM(_xlfn.XLOOKUP(D21, Move_List!$A:$A, Move_List!$C:$C)))="SPECIAL", I21, TRUE, 0), 0)} -> 9900 | O21: {=IFERROR( _xlfn.XLOOKUP(D21, Move_List!$A:$A, Move_List!$D:$D) * _xlfn.IFS( ISNUMBER(SEARCH("Max", E21)), LOOKUP(_xlfn.XLOOKUP(D21, Move_List!$A:$A, Move_List!$D:$D), {0,60,80,110,150}, {2.5,1.83,1.63,1.27,1}), E21<>"", LOOKUP(_xlfn.XLOOKUP(D21, Move_List!$A:$A, Move_List!$D:$D), {0,60,80,90,100,110,120,150}, {2.5,2,2,1.94,1.8,1.68,1.58,1.33}), TRUE, 0 ) * IF(_xlfn.XLOOKUP(D21, Move_List!$A:$A, Move_List!$C:$C)="Physical", K21, I21), 0)} -> 16137 | P21: =(J21 + L21 + M21) / 3 -> 97.333333 | Q21: =IF(O21>0, (N21+O21)/2, N21) * (P21 / 100) -> 12671.34 | R21: {=IFERROR(Q21 / IF(OR(_xlfn.IFNA(_xlfn.XLOOKUP(E21, Move_List!$A:$A, Move_List!$C:$C), "")={"Dynamax","Mega"}), G21*1.2, G21), 0)} -> 111.15211
A22: 1-1-011 | B22: Vaporeon | C22: =_xlfn.XLOOKUP(A22,Stars!A:A,Stars!C:C) -> 5-star | D22: Hydro Pump | F22: 1 | G22: 108 | H22: 62 | I22: 101 | J22: 88 | K22: 62 | L22: 57 | M22: 168 | N22: {=IFERROR(_xlfn.XLOOKUP(D22, Move_List!$A:$A, Move_List!$D:$D) * _xlfn.IFS(UPPER(TRIM(_xlfn.XLOOKUP(D22, Move_List!$A:$A, Move_List!$C:$C)))="PHYSICAL", K22, UPPER(TRIM(_xlfn.XLOOKUP(D22, Move_List!$A:$A, Move_List!$C:$C)))="SPECIAL", I22, TRUE, 0), 0)} -> 11110 | O22: {=IFERROR( _xlfn.XLOOKUP(D22, Move_List!$A:$A, Move_List!$D:$D) * _xlfn.IFS( ISNUMBER(SEARCH("Max", E22)), LOOKUP(_xlfn.XLOOKUP(D22, Move_List!$A:$A, Move_List!$D:$D), {0,60,80,110,150}, {2.5,1.83,1.63,1.27,1}), E22<>"", LOOKUP(_xlfn.XLOOKUP(D22, Move_List!$A:$A, Move_List!$D:$D), {0,60,80,90,100,110,120,150}, {2.5,2,2,1.94,1.8,1.68,1.58,1.33}), TRUE, 0 ) * IF(_xlfn.XLOOKUP(D22, Move_List!$A:$A, Move_List!$C:$C)="Physical", K22, I22), 0)} -> 0 | P22: =(J22 + L22 + M22) / 3 -> 104.33333 | Q22: =IF(O22>0, (N22+O22)/2, N22) * (P22 / 100) -> 11591.433 | R22: {=IFERROR(Q22 / IF(OR(_xlfn.IFNA(_xlfn.XLOOKUP(E22, Move_List!$A:$A, Move_List!$C:$C), "")={"Dynamax","Mega"}), G22*1.2, G22), 0)} -> 107.32809
A23: 1-2-007 | B23: Gardevoir | C23: =_xlfn.XLOOKUP(A23,Stars!A:A,Stars!C:C) -> 6-star | D23: Psychic | F23: 0.95 | G23: 124 | H23: 88 | I23: 135 | J23: 124 | K23: 72 | L23: 72 | M23: 132 | N23: {=IFERROR(_xlfn.XLOOKUP(D23, Move_List!$A:$A, Move_List!$D:$D) * _xlfn.IFS(UPPER(TRIM(_xlfn.XLOOKUP(D23, Move_List!$A:$A, Move_List!$C:$C)))="PHYSICAL", K23, UPPER(TRIM(_xlfn.XLOOKUP(D23, Move_List!$A:$A, Move_List!$C:$C)))="SPECIAL", I23, TRUE, 0), 0)} -> 12150 | O23: {=IFERROR( _xlfn.XLOOKUP(D23, Move_List!$A:$A, Move_List!$D:$D) * _xlfn.IFS( ISNUMBER(SEARCH("Max", E23)), LOOKUP(_xlfn.XLOOKUP(D23, Move_List!$A:$A, Move_List!$D:$D), {0,60,80,110,150}, {2.5,1.83,1.63,1.27,1}), E23<>"", LOOKUP(_xlfn.XLOOKUP(D23, Move_List!$A:$A, Move_List!$D:$D), {0,60,80,90,100,110,120,150}, {2.5,2,2,1.94,1.8,1.68,1.58,1.33}), TRUE, 0 ) * IF(_xlfn.XLOOKUP(D23, Move_List!$A:$A, Move_List!$C:$C)="Physical", K23, I23), 0)} -> 0 | P23: =(J23 + L23 + M23) / 3 -> 109.33333 | Q23: =IF(O23>0, (N23+O23)/2, N23) * (P23 / 100) -> 13284 | R23: {=IFERROR(Q23 / IF(OR(_xlfn.IFNA(_xlfn.XLOOKUP(E23, Move_List!$A:$A, Move_List!$C:$C), "")={"Dynamax","Mega"}), G23*1.2, G23), 0)} -> 107.12903
A24: 1-1-022 | B24: Cinderace | C24: =_xlfn.XLOOKUP(A24,Stars!A:A,Stars!C:C) -> 5-star | D24: Pyro Ball | F24: 1 | G24: 108 | H24: 109 | I24: 62 | J24: 71 | K24: 107 | L24: 71 | M24: 124 | N24: {=IFERROR(_xlfn.XLOOKUP(D24, Move_List!$A:$A, Move_List!$D:$D) * _xlfn.IFS(UPPER(TRIM(_xlfn.XLOOKUP(D24, Move_List!$A:$A, Move_List!$C:$C)))="PHYSICAL", K24, UPPER(TRIM(_xlfn.XLOOKUP(D24, Move_List!$A:$A, Move_List!$C:$C)))="SPECIAL", I24, TRUE, 0), 0)} -> 12840 | O24: {=IFERROR( _xlfn.XLOOKUP(D24, Move_List!$A:$A, Move_List!$D:$D) * _xlfn.IFS( ISNUMBER(SEARCH("Max", E24)), LOOKUP(_xlfn.XLOOKUP(D24, Move_List!$A:$A, Move_List!$D:$D), {0,60,80,110,150}, {2.5,1.83,1.63,1.27,1}), E24<>"", LOOKUP(_xlfn.XLOOKUP(D24, Move_List!$A:$A, Move_List!$D:$D), {0,60,80,90,100,110,120,150}, {2.5,2,2,1.94,1.8,1.68,1.58,1.33}), TRUE, 0 ) * IF(_xlfn.XLOOKUP(D24, Move_List!$A:$A, Move_List!$C:$C)="Physical", K24, I24), 0)} -> 0 | P24: =(J24 + L24 + M24) / 3 -> 88.666667 | Q24: =IF(O24>0, (N24+O24)/2, N24) * (P24 / 100) -> 11384.8 | R24: {=IFERROR(Q24 / IF(OR(_xlfn.IFNA(_xlfn.XLOOKUP(E24, Move_List!$A:$A, Move_List!$C:$C), "")={"Dynamax","Mega"}), G24*1.2, G24), 0)} -> 105.41481
A25: R-1-2 | B25: Lucario | C25: =_xlfn.XLOOKUP(A25,Stars!A:A,Stars!C:C) -> Special | D25: Focus Blast | E25: Max Knuckle | F25: 1 | G25: 102 | H25: 80 | I25: 101 | J25: 63 | K25: 97 | L25: 63 | M25: 110 | N25: {=IFERROR(_xlfn.XLOOKUP(D25, Move_List!$A:$A, Move_List!$D:$D) * _xlfn.IFS(UPPER(TRIM(_xlfn.XLOOKUP(D25, Move_List!$A:$A, Move_List!$C:$C)))="PHYSICAL", K25, UPPER(TRIM(_xlfn.XLOOKUP(D25, Move_List!$A:$A, Move_List!$C:$C)))="SPECIAL", I25, TRUE, 0), 0)} -> 12120 | O25: {=IFERROR( _xlfn.XLOOKUP(D25, Move_List!$A:$A, Move_List!$D:$D) * _xlfn.IFS( ISNUMBER(SEARCH("Max", E25)), LOOKUP(_xlfn.XLOOKUP(D25, Move_List!$A:$A, Move_List!$D:$D), {0,60,80,110,150}, {2.5,1.83,1.63,1.27,1}), E25<>"", LOOKUP(_xlfn.XLOOKUP(D25, Move_List!$A:$A, Move_List!$D:$D), {0,60,80,90,100,110,120,150}, {2.5,2,2,1.94,1.8,1.68,1.58,1.33}), TRUE, 0 ) * IF(_xlfn.XLOOKUP(D25, Move_List!$A:$A, Move_List!$C:$C)="Physical", K25, I25), 0)} -> 15392.4 | P25: =(J25 + L25 + M25) / 3 -> 78.666667 | Q25: =IF(O25>0, (N25+O25)/2, N25) * (P25 / 100) -> 10821.544 | R25: {=IFERROR(Q25 / IF(OR(_xlfn.IFNA(_xlfn.XLOOKUP(E25, Move_List!$A:$A, Move_List!$C:$C), "")={"Dynamax","Mega"}), G25*1.2, G25), 0)} -> 106.09357
A26: 1-2-014 | B26: Sylveon | C26: =_xlfn.XLOOKUP(A26,Stars!A:A,Stars!C:C) -> 5-star | D26: Moonblast | F26: 0.95 | G26: 116 | H26: 62 | I26: 110 | J26: 129 | K26: 67 | L26: 67 | M26: 149 | N26: {=IFERROR(_xlfn.XLOOKUP(D26, Move_List!$A:$A, Move_List!$D:$D) * _xlfn.IFS(UPPER(TRIM(_xlfn.XLOOKUP(D26, Move_List!$A:$A, Move_List!$C:$C)))="PHYSICAL", K26, UPPER(TRIM(_xlfn.XLOOKUP(D26, Move_List!$A:$A, Move_List!$C:$C)))="SPECIAL", I26, TRUE, 0), 0)} -> 10450 | O26: {=IFERROR( _xlfn.XLOOKUP(D26, Move_List!$A:$A, Move_List!$D:$D) * _xlfn.IFS( ISNUMBER(SEARCH("Max", E26)), LOOKUP(_xlfn.XLOOKUP(D26, Move_List!$A:$A, Move_List!$D:$D), {0,60,80,110,150}, {2.5,1.83,1.63,1.27,1}), E26<>"", LOOKUP(_xlfn.XLOOKUP(D26, Move_List!$A:$A, Move_List!$D:$D), {0,60,80,90,100,110,120,150}, {2.5,2,2,1.94,1.8,1.68,1.58,1.33}), TRUE, 0 ) * IF(_xlfn.XLOOKUP(D26, Move_List!$A:$A, Move_List!$C:$C)="Physical", K26, I26), 0)} -> 0 | P26: =(J26 + L26 + M26) / 3 -> 115 | Q26: =IF(O26>0, (N26+O26)/2, N26) * (P26 / 100) -> 12017.5 | R26: {=IFERROR(Q26 / IF(OR(_xlfn.IFNA(_xlfn.XLOOKUP(E26, Move_List!$A:$A, Move_List!$C:$C), "")={"Dynamax","Mega"}), G26*1.2, G26), 0)} -> 103.59914
A27: 1-2-016 | B27: Torterra | C27: =_xlfn.XLOOKUP(A27,Stars!A:A,Stars!C:C) -> 5-star | D27: Earthquake | E27: Tectonic Rage | F27: 1 | G27: 112 | H27: 56 | I27: 74 | J27: 83 | K27: 105 | L27: 101 | M27: 143 | N27: {=IFERROR(_xlfn.XLOOKUP(D27, Move_List!$A:$A, Move_List!$D:$D) * _xlfn.IFS(UPPER(TRIM(_xlfn.XLOOKUP(D27, Move_List!$A:$A, Move_List!$C:$C)))="PHYSICAL", K27, UPPER(TRIM(_xlfn.XLOOKUP(D27, Move_List!$A:$A, Move_List!$C:$C)))="SPECIAL", I27, TRUE, 0), 0)} -> 10500 | O27: {=IFERROR( _xlfn.XLOOKUP(D27, Move_List!$A:$A, Move_List!$D:$D) * _xlfn.IFS( ISNUMBER(SEARCH("Max", E27)), LOOKUP(_xlfn.XLOOKUP(D27, Move_List!$A:$A, Move_List!$D:$D), {0,60,80,110,150}, {2.5,1.83,1.63,1.27,1}), E27<>"", LOOKUP(_xlfn.XLOOKUP(D27, Move_List!$A:$A, Move_List!$D:$D), {0,60,80,90,100,110,120,150}, {2.5,2,2,1.94,1.8,1.68,1.58,1.33}), TRUE, 0 ) * IF(_xlfn.XLOOKUP(D27, Move_List!$A:$A, Move_List!$C:$C)="Physical", K27, I27), 0)} -> 18900 | P27: =(J27 + L27 + M27) / 3 -> 109 | Q27: =IF(O27>0, (N27+O27)/2, N27) * (P27 / 100) -> 16023 | R27: {=IFERROR(Q27 / IF(OR(_xlfn.IFNA(_xlfn.XLOOKUP(E27, Move_List!$A:$A, Move_List!$C:$C), "")={"Dynamax","Mega"}), G27*1.2, G27), 0)} -> 143.0625
A28: 1-1-056 | B28: Mudsdale | C28: =_xlfn.XLOOKUP(A28,Stars!A:A,Stars!C:C) -> 4-star | D28: High Horsepower | F28: 1 | G28: 90 | H28: 31 | I28: 46 | J28: 69 | K28: 100 | L28: 81 | M28: 124 | N28: {=IFERROR(_xlfn.XLOOKUP(D28, Move_List!$A:$A, Move_List!$D:$D) * _xlfn.IFS(UPPER(TRIM(_xlfn.XLOOKUP(D28, Move_List!$A:$A, Move_List!$C:$C)))="PHYSICAL", K28, UPPER(TRIM(_xlfn.XLOOKUP(D28, Move_List!$A:$A, Move_List!$C:$C)))="SPECIAL", I28, TRUE, 0), 0)} -> 9500 | O28: {=IFERROR( _xlfn.XLOOKUP(D28, Move_List!$A:$A, Move_List!$D:$D) * _xlfn.IFS( ISNUMBER(SEARCH("Max", E28)), LOOKUP(_xlfn.XLOOKUP(D28, Move_List!$A:$A, Move_List!$D:$D), {0,60,80,110,150}, {2.5,1.83,1.63,1.27,1}), E28<>"", LOOKUP(_xlfn.XLOOKUP(D28, Move_List!$A:$A, Move_List!$D:$D), {0,60,80,90,100,110,120,150}, {2.5,2,2,1.94,1.8,1.68,1.58,1.33}), TRUE, 0 ) * IF(_xlfn.XLOOKUP(D28, Move_List!$A:$A, Move_List!$C:$C)="Physical", K28, I28), 0)} -> 0 | P28: =(J28 + L28 + M28) / 3 -> 91.333333 | Q28: =IF(O28>0, (N28+O28)/2, N28) * (P28 / 100) -> 8676.6667 | R28: {=IFERROR(Q28 / IF(OR(_xlfn.IFNA(_xlfn.XLOOKUP(E28, Move_List!$A:$A, Move_List!$C:$C), "")={"Dynamax","Mega"}), G28*1.2, G28), 0)} -> 96.407407
A29: 1-1-010 | B29: Blastoise | C29: =_xlfn.XLOOKUP(A29,Stars!A:A,Stars!C:C) -> 6-star | D29: Hydro Pump | F29: 1 | G29: 124 | H29: 83 | I29: 90 | J29: 110 | K29: 88 | L29: 105 | M29: 139 | N29: {=IFERROR(_xlfn.XLOOKUP(D29, Move_List!$A:$A, Move_List!$D:$D) * _xlfn.IFS(UPPER(TRIM(_xlfn.XLOOKUP(D29, Move_List!$A:$A, Move_List!$C:$C)))="PHYSICAL", K29, UPPER(TRIM(_xlfn.XLOOKUP(D29, Move_List!$A:$A, Move_List!$C:$C)))="SPECIAL", I29, TRUE, 0), 0)} -> 9900 | O29: {=IFERROR( _xlfn.XLOOKUP(D29, Move_List!$A:$A, Move_List!$D:$D) * _xlfn.IFS( ISNUMBER(SEARCH("Max", E29)), LOOKUP(_xlfn.XLOOKUP(D29, Move_List!$A:$A, Move_List!$D:$D), {0,60,80,110,150}, {2.5,1.83,1.63,1.27,1}), E29<>"", LOOKUP(_xlfn.XLOOKUP(D29, Move_List!$A:$A, Move_List!$D:$D), {0,60,80,90,100,110,120,150}, {2.5,2,2,1.94,1.8,1.68,1.58,1.33}), TRUE, 0 ) * IF(_xlfn.XLOOKUP(D29, Move_List!$A:$A, Move_List!$C:$C)="Physical", K29, I29), 0)} -> 0 | P29: =(J29 + L29 + M29) / 3 -> 118 | Q29: =IF(O29>0, (N29+O29)/2, N29) * (P29 / 100) -> 11682 | R29: {=IFERROR(Q29 / IF(OR(_xlfn.IFNA(_xlfn.XLOOKUP(E29, Move_List!$A:$A, Move_List!$C:$C), "")={"Dynamax","Mega"}), G29*1.2, G29), 0)} -> 94.209677
A30: 1-2-017 | B30: Infernape | C30: =_xlfn.XLOOKUP(A30,Stars!A:A,Stars!C:C) -> 5-star | D30: Close Combat | E30: All-Out Pummeling | F30: 1 | G30: 114 | H30: 104 | I30: 100 | J30: 70 | K30: 100 | L30: 70 | M30: 125 | N30: {=IFERROR(_xlfn.XLOOKUP(D30, Move_List!$A:$A, Move_List!$D:$D) * _xlfn.IFS(UPPER(TRIM(_xlfn.XLOOKUP(D30, Move_List!$A:$A, Move_List!$C:$C)))="PHYSICAL", K30, UPPER(TRIM(_xlfn.XLOOKUP(D30, Move_List!$A:$A, Move_List!$C:$C)))="SPECIAL", I30, TRUE, 0), 0)} -> 12000 | O30: {=IFERROR( _xlfn.XLOOKUP(D30, Move_List!$A:$A, Move_List!$D:$D) * _xlfn.IFS( ISNUMBER(SEARCH("Max", E30)), LOOKUP(_xlfn.XLOOKUP(D30, Move_List!$A:$A, Move_List!$D:$D), {0,60,80,110,150}, {2.5,1.83,1.63,1.27,1}), E30<>"", LOOKUP(_xlfn.XLOOKUP(D30, Move_List!$A:$A, Move_List!$D:$D), {0,60,80,90,100,110,120,150}, {2.5,2,2,1.94,1.8,1.68,1.58,1.33}), TRUE, 0 ) * IF(_xlfn.XLOOKUP(D30, Move_List!$A:$A, Move_List!$C:$C)="Physical", K30, I30), 0)} -> 18960 | P30: =(J30 + L30 + M30) / 3 -> 88.333333 | Q30: =IF(O30>0, (N30+O30)/2, N30) * (P30 / 100) -> 13674 | R30: {=IFERROR(Q30 / IF(OR(_xlfn.IFNA(_xlfn.XLOOKUP(E30, Move_List!$A:$A, Move_List!$C:$C), "")={"Dynamax","Mega"}), G30*1.2, G30), 0)} -> 119.94737
A31: 1-2-008 | B31: Reshiram | C31: =_xlfn.XLOOKUP(A31,Stars!A:A,Stars!C:C) -> 6-star | D31: Fusion Flare | F31: 1 | G31: 162 | H31: 84 | I31: 137 | J31: 124 | K31: 72 | L31: 72 | M31: 132 | N31: {=IFERROR(_xlfn.XLOOKUP(D31, Move_List!$A:$A, Move_List!$D:$D) * _xlfn.IFS(UPPER(TRIM(_xlfn.XLOOKUP(D31, Move_List!$A:$A, Move_List!$C:$C)))="PHYSICAL", K31, UPPER(TRIM(_xlfn.XLOOKUP(D31, Move_List!$A:$A, Move_List!$C:$C)))="SPECIAL", I31, TRUE, 0), 0)} -> 13700 | O31: {=IFERROR( _xlfn.XLOOKUP(D31, Move_List!$A:$A, Move_List!$D:$D) * _xlfn.IFS( ISNUMBER(SEARCH("Max", E31)), LOOKUP(_xlfn.XLOOKUP(D31, Move_List!$A:$A, Move_List!$D:$D), {0,60,80,110,150}, {2.5,1.83,1.63,1.27,1}), E31<>"", LOOKUP(_xlfn.XLOOKUP(D31, Move_List!$A:$A, Move_List!$D:$D), {0,60,80,90,100,110,120,150}, {2.5,2,2,1.94,1.8,1.68,1.58,1.33}), TRUE, 0 ) * IF(_xlfn.XLOOKUP(D31, Move_List!$A:$A, Move_List!$C:$C)="Physical", K31, I31), 0)} -> 0 | P31: =(J31 + L31 + M31) / 3 -> 109.33333 | Q31: =IF(O31>0, (N31+O31)/2, N31) * (P31 / 100) -> 14978.667 | R31: {=IFERROR(Q31 / IF(OR(_xlfn.IFNA(_xlfn.XLOOKUP(E31, Move_List!$A:$A, Move_List!$C:$C), "")={"Dynamax","Mega"}), G31*1.2, G31), 0)} -> 92.460905
A32: 1-1-062 | B32: Vikavolt | C32: =_xlfn.XLOOKUP(A32,Stars!A:A,Stars!C:C) -> 4-star | D32: Thunderbolt | F32: 1 | G32: 88 | H32: 35 | I32: 113 | J32: 60 | K32: 56 | L32: 71 | M32: 103 | N32: {=IFERROR(_xlfn.XLOOKUP(D32, Move_List!$A:$A, Move_List!$D:$D) * _xlfn.IFS(UPPER(TRIM(_xlfn.XLOOKUP(D32, Move_List!$A:$A, Move_List!$C:$C)))="PHYSICAL", K32, UPPER(TRIM(_xlfn.XLOOKUP(D32, Move_List!$A:$A, Move_List!$C:$C)))="SPECIAL", I32, TRUE, 0), 0)} -> 10170 | O32: {=IFERROR( _xlfn.XLOOKUP(D32, Move_List!$A:$A, Move_List!$D:$D) * _xlfn.IFS( ISNUMBER(SEARCH("Max", E32)), LOOKUP(_xlfn.XLOOKUP(D32, Move_List!$A:$A, Move_List!$D:$D), {0,60,80,110,150}, {2.5,1.83,1.63,1.27,1}), E32<>"", LOOKUP(_xlfn.XLOOKUP(D32, Move_List!$A:$A, Move_List!$D:$D), {0,60,80,90,100,110,120,150}, {2.5,2,2,1.94,1.8,1.68,1.58,1.33}), TRUE, 0 ) * IF(_xlfn.XLOOKUP(D32, Move_List!$A:$A, Move_List!$C:$C)="Physical", K32, I32), 0)} -> 0 | P32: =(J32 + L32 + M32) / 3 -> 78 | Q32: =IF(O32>0, (N32+O32)/2, N32) * (P32 / 100) -> 7932.6 | R32: {=IFERROR(Q32 / IF(OR(_xlfn.IFNA(_xlfn.XLOOKUP(E32, Move_List!$A:$A, Move_List!$C:$C), "")={"Dynamax","Mega"}), G32*1.2, G32), 0)} -> 90.143182
A33: 1-1-025 | B33: Keldeo | C33: =_xlfn.XLOOKUP(A33,Stars!A:A,Stars!C:C) -> 5-star | D33: Secret Sword | F33: 1 | G33: 122 | H33: 104 | I33: 123 | J33: 87 | K33: 71 | L33: 87 | M33: 139 | N33: {=IFERROR(_xlfn.XLOOKUP(D33, Move_List!$A:$A, Move_List!$D:$D) * _xlfn.IFS(UPPER(TRIM(_xlfn.XLOOKUP(D33, Move_List!$A:$A, Move_List!$C:$C)))="PHYSICAL", K33, UPPER(TRIM(_xlfn.XLOOKUP(D33, Move_List!$A:$A, Move_List!$C:$C)))="SPECIAL", I33, TRUE, 0), 0)} -> 10455 | O33: {=IFERROR( _xlfn.XLOOKUP(D33, Move_List!$A:$A, Move_List!$D:$D) * _xlfn.IFS( ISNUMBER(SEARCH("Max", E33)), LOOKUP(_xlfn.XLOOKUP(D33, Move_List!$A:$A, Move_List!$D:$D), {0,60,80,110,150}, {2.5,1.83,1.63,1.27,1}), E33<>"", LOOKUP(_xlfn.XLOOKUP(D33, Move_List!$A:$A, Move_List!$D:$D), {0,60,80,90,100,110,120,150}, {2.5,2,2,1.94,1.8,1.68,1.58,1.33}), TRUE, 0 ) * IF(_xlfn.XLOOKUP(D33, Move_List!$A:$A, Move_List!$C:$C)="Physical", K33, I33), 0)} -> 0 | P33: =(J33 + L33 + M33) / 3 -> 104.33333 | Q33: =IF(O33>0, (N33+O33)/2, N33) * (P33 / 100) -> 10908.05 | R33: {=IFERROR(Q33 / IF(OR(_xlfn.IFNA(_xlfn.XLOOKUP(E33, Move_List!$A:$A, Move_List!$C:$C), "")={"Dynamax","Mega"}), G33*1.2, G33), 0)} -> 89.410246
A34: 1-2-012 | B34: Espeon | C34: =_xlfn.XLOOKUP(A34,Stars!A:A,Stars!C:C) -> 5-star | D34: Psychic | F34: 1 | G34: 112 | H34: 106 | I34: 124 | J34: 92 | K34: 64 | L34: 60 | M34: 115 | N34: {=IFERROR(_xlfn.XLOOKUP(D34, Move_List!$A:$A, Move_List!$D:$D) * _xlfn.IFS(UPPER(TRIM(_xlfn.XLOOKUP(D34, Move_List!$A:$A, Move_List!$C:$C)))="PHYSICAL", K34, UPPER(TRIM(_xlfn.XLOOKUP(D34, Move_List!$A:$A, Move_List!$C:$C)))="SPECIAL", I34, TRUE, 0), 0)} -> 11160 | O34: {=IFERROR( _xlfn.XLOOKUP(D34, Move_List!$A:$A, Move_List!$D:$D) * _xlfn.IFS( ISNUMBER(SEARCH("Max", E34)), LOOKUP(_xlfn.XLOOKUP(D34, Move_List!$A:$A, Move_List!$D:$D), {0,60,80,110,150}, {2.5,1.83,1.63,1.27,1}), E34<>"", LOOKUP(_xlfn.XLOOKUP(D34, Move_List!$A:$A, Move_List!$D:$D), {0,60,80,90,100,110,120,150}, {2.5,2,2,1.94,1.8,1.68,1.58,1.33}), TRUE, 0 ) * IF(_xlfn.XLOOKUP(D34, Move_List!$A:$A, Move_List!$C:$C)="Physical", K34, I34), 0)} -> 0 | P34: =(J34 + L34 + M34) / 3 -> 89 | Q34: =IF(O34>0, (N34+O34)/2, N34) * (P34 / 100) -> 9932.4 | R34: {=IFERROR(Q34 / IF(OR(_xlfn.IFNA(_xlfn.XLOOKUP(E34, Move_List!$A:$A, Move_List!$C:$C), "")={"Dynamax","Mega"}), G34*1.2, G34), 0)} -> 88.682143
A35: 1-1-002 | B35: Mew | C35: =_xlfn.XLOOKUP(A35,Stars!A:A,Stars!C:C) -> 6-star | D35: Psychic | F35: 1 | G35: 142 | H35: 109 | I35: 109 | J35: 109 | K35: 109 | L35: 109 | M35: 166 | N35: {=IFERROR(_xlfn.XLOOKUP(D35, Move_List!$A:$A, Move_List!$D:$D) * _xlfn.IFS(UPPER(TRIM(_xlfn.XLOOKUP(D35, Move_List!$A:$A, Move_List!$C:$C)))="PHYSICAL", K35, UPPER(TRIM(_xlfn.XLOOKUP(D35, Move_List!$A:$A, Move_List!$C:$C)))="SPECIAL", I35, TRUE, 0), 0)} -> 9810 | O35: {=IFERROR( _xlfn.XLOOKUP(D35, Move_List!$A:$A, Move_List!$D:$D) * _xlfn.IFS( ISNUMBER(SEARCH("Max", E35)), LOOKUP(_xlfn.XLOOKUP(D35, Move_List!$A:$A, Move_List!$D:$D), {0,60,80,110,150}, {2.5,1.83,1.63,1.27,1}), E35<>"", LOOKUP(_xlfn.XLOOKUP(D35, Move_List!$A:$A, Move_List!$D:$D), {0,60,80,90,100,110,120,150}, {2.5,2,2,1.94,1.8,1.68,1.58,1.33}), TRUE, 0 ) * IF(_xlfn.XLOOKUP(D35, Move_List!$A:$A, Move_List!$C:$C)="Physical", K35, I35), 0)} -> 0 | P35: =(J35 + L35 + M35) / 3 -> 128 | Q35: =IF(O35>0, (N35+O35)/2, N35) * (P35 / 100) -> 12556.8 | R35: {=IFERROR(Q35 / IF(OR(_xlfn.IFNA(_xlfn.XLOOKUP(E35, Move_List!$A:$A, Move_List!$C:$C), "")={"Dynamax","Mega"}), G35*1.2, G35), 0)} -> 88.428169
A36: 1-2-013 | B36: Leafeon | C36: =_xlfn.XLOOKUP(A36,Stars!A:A,Stars!C:C) -> 5-star | D36: Leaf Blade | F36: 1 | G36: 114 | H36: 94 | I36: 61 | J36: 66 | K36: 108 | L36: 127 | M36: 118 | N36: {=IFERROR(_xlfn.XLOOKUP(D36, Move_List!$A:$A, Move_List!$D:$D) * _xlfn.IFS(UPPER(TRIM(_xlfn.XLOOKUP(D36, Move_List!$A:$A, Move_List!$C:$C)))="PHYSICAL", K36, UPPER(TRIM(_xlfn.XLOOKUP(D36, Move_List!$A:$A, Move_List!$C:$C)))="SPECIAL", I36, TRUE, 0), 0)} -> 9720 | O36: {=IFERROR( _xlfn.XLOOKUP(D36, Move_List!$A:$A, Move_List!$D:$D) * _xlfn.IFS( ISNUMBER(SEARCH("Max", E36)), LOOKUP(_xlfn.XLOOKUP(D36, Move_List!$A:$A, Move_List!$D:$D), {0,60,80,110,150}, {2.5,1.83,1.63,1.27,1}), E36<>"", LOOKUP(_xlfn.XLOOKUP(D36, Move_List!$A:$A, Move_List!$D:$D), {0,60,80,90,100,110,120,150}, {2.5,2,2,1.94,1.8,1.68,1.58,1.33}), TRUE, 0 ) * IF(_xlfn.XLOOKUP(D36, Move_List!$A:$A, Move_List!$C:$C)="Physical", K36, I36), 0)} -> 0 | P36: =(J36 + L36 + M36) / 3 -> 103.66667 | Q36: =IF(O36>0, (N36+O36)/2, N36) * (P36 / 100) -> 10076.4 | R36: {=IFERROR(Q36 / IF(OR(_xlfn.IFNA(_xlfn.XLOOKUP(E36, Move_List!$A:$A, Move_List!$C:$C), "")={"Dynamax","Mega"}), G36*1.2, G36), 0)} -> 88.389474
A37: 1-2-019 | B37: Alolan Ninetales | C37: =_xlfn.XLOOKUP(A37,Stars!A:A,Stars!C:C) -> 5-star | D37: Blizzard | F37: 0.7 | G37: 122 | H37: 118 | I37: 89 | J37: 109 | K37: 74 | L37: 83 | M37: 137 | N37: {=IFERROR(_xlfn.XLOOKUP(D37, Move_List!$A:$A, Move_List!$D:$D) * _xlfn.IFS(UPPER(TRIM(_xlfn.XLOOKUP(D37, Move_List!$A:$A, Move_List!$C:$C)))="PHYSICAL", K37, UPPER(TRIM(_xlfn.XLOOKUP(D37, Move_List!$A:$A, Move_List!$C:$C)))="SPECIAL", I37, TRUE, 0), 0)} -> 9790 | O37: {=IFERROR( _xlfn.XLOOKUP(D37, Move_List!$A:$A, Move_List!$D:$D) * _xlfn.IFS( ISNUMBER(SEARCH("Max", E37)), LOOKUP(_xlfn.XLOOKUP(D37, Move_List!$A:$A, Move_List!$D:$D), {0,60,80,110,150}, {2.5,1.83,1.63,1.27,1}), E37<>"", LOOKUP(_xlfn.XLOOKUP(D37, Move_List!$A:$A, Move_List!$D:$D), {0,60,80,90,100,110,120,150}, {2.5,2,2,1.94,1.8,1.68,1.58,1.33}), TRUE, 0 ) * IF(_xlfn.XLOOKUP(D37, Move_List!$A:$A, Move_List!$C:$C)="Physical", K37, I37), 0)} -> 0 | P37: =(J37 + L37 + M37) / 3 -> 109.66667 | Q37: =IF(O37>0, (N37+O37)/2, N37) * (P37 / 100) -> 10736.367 | R37: {=IFERROR(Q37 / IF(OR(_xlfn.IFNA(_xlfn.XLOOKUP(E37, Move_List!$A:$A, Move_List!$C:$C), "")={"Dynamax","Mega"}), G37*1.2, G37), 0)} -> 88.003005
A38: 1-2-011 | B38: Jolteon | C38: =_xlfn.XLOOKUP(A38,Stars!A:A,Stars!C:C) -> 5-star | D38: Thunder | F38: 0.7 | G38: 108 | H38: 119 | I38: 101 | J38: 88 | K38: 62 | L38: 57 | M38: 111 | N38: {=IFERROR(_xlfn.XLOOKUP(D38, Move_List!$A:$A, Move_List!$D:$D) * _xlfn.IFS(UPPER(TRIM(_xlfn.XLOOKUP(D38, Move_List!$A:$A, Move_List!$C:$C)))="PHYSICAL", K38, UPPER(TRIM(_xlfn.XLOOKUP(D38, Move_List!$A:$A, Move_List!$C:$C)))="SPECIAL", I38, TRUE, 0), 0)} -> 11110 | O38: {=IFERROR( _xlfn.XLOOKUP(D38, Move_List!$A:$A, Move_List!$D:$D) * _xlfn.IFS( ISNUMBER(SEARCH("Max", E38)), LOOKUP(_xlfn.XLOOKUP(D38, Move_List!$A:$A, Move_List!$D:$D), {0,60,80,110,150}, {2.5,1.83,1.63,1.27,1}), E38<>"", LOOKUP(_xlfn.XLOOKUP(D38, Move_List!$A:$A, Move_List!$D:$D), {0,60,80,90,100,110,120,150}, {2.5,2,2,1.94,1.8,1.68,1.58,1.33}), TRUE, 0 ) * IF(_xlfn.XLOOKUP(D38, Move_List!$A:$A, Move_List!$C:$C)="Physical", K38, I38), 0)} -> 0 | P38: =(J38 + L38 + M38) / 3 -> 85.333333 | Q38: =IF(O38>0, (N38+O38)/2, N38) * (P38 / 100) -> 9480.5333 | R38: {=IFERROR(Q38 / IF(OR(_xlfn.IFNA(_xlfn.XLOOKUP(E38, Move_List!$A:$A, Move_List!$C:$C), "")={"Dynamax","Mega"}), G38*1.2, G38), 0)} -> 87.782716
A39: 1-2-025 | B39: Drednaw | C39: =_xlfn.XLOOKUP(A39,Stars!A:A,Stars!C:C) -> 5-star | D39: Liquidation | F39: 1 | G39: 104 | H39: 73 | I39: 48 | J39: 67 | K39: 110 | L39: 87 | M39: 138 | N39: {=IFERROR(_xlfn.XLOOKUP(D39, Move_List!$A:$A, Move_List!$D:$D) * _xlfn.IFS(UPPER(TRIM(_xlfn.XLOOKUP(D39, Move_List!$A:$A, Move_List!$C:$C)))="PHYSICAL", K39, UPPER(TRIM(_xlfn.XLOOKUP(D39, Move_List!$A:$A, Move_List!$C:$C)))="SPECIAL", I39, TRUE, 0), 0)} -> 9350 | O39: {=IFERROR( _xlfn.XLOOKUP(D39, Move_List!$A:$A, Move_List!$D:$D) * _xlfn.IFS( ISNUMBER(SEARCH("Max", E39)), LOOKUP(_xlfn.XLOOKUP(D39, Move_List!$A:$A, Move_List!$D:$D), {0,60,80,110,150}, {2.5,1.83,1.63,1.27,1}), E39<>"", LOOKUP(_xlfn.XLOOKUP(D39, Move_List!$A:$A, Move_List!$D:$D), {0,60,80,90,100,110,120,150}, {2.5,2,2,1.94,1.8,1.68,1.58,1.33}), TRUE, 0 ) * IF(_xlfn.XLOOKUP(D39, Move_List!$A:$A, Move_List!$C:$C)="Physical", K39, I39), 0)} -> 0 | P39: =(J39 + L39 + M39) / 3 -> 97.333333 | Q39: =IF(O39>0, (N39+O39)/2, N39) * (P39 / 100) -> 9100.6667 | R39: {=IFERROR(Q39 / IF(OR(_xlfn.IFNA(_xlfn.XLOOKUP(E39, Move_List!$A:$A, Move_List!$C:$C), "")={"Dynamax","Mega"}), G39*1.2, G39), 0)} -> 87.50641
A40: 1-1-009 | B40: Charizard | C40: =_xlfn.XLOOKUP(A40,Stars!A:A,Stars!C:C) -> 6-star | D40: Flamethrower | F40: 1 | G40: 124 | H40: 105 | I40: 114 | J40: 90 | K40: 89 | L40: 83 | M40: 138 | N40: {=IFERROR(_xlfn.XLOOKUP(D40, Move_List!$A:$A, Move_List!$D:$D) * _xlfn.IFS(UPPER(TRIM(_xlfn.XLOOKUP(D40, Move_List!$A:$A, Move_List!$C:$C)))="PHYSICAL", K40, UPPER(TRIM(_xlfn.XLOOKUP(D40, Move_List!$A:$A, Move_List!$C:$C)))="SPECIAL", I40, TRUE, 0), 0)} -> 10260 | O40: {=IFERROR( _xlfn.XLOOKUP(D40, Move_List!$A:$A, Move_List!$D:$D) * _xlfn.IFS( ISNUMBER(SEARCH("Max", E40)), LOOKUP(_xlfn.XLOOKUP(D40, Move_List!$A:$A, Move_List!$D:$D), {0,60,80,110,150}, {2.5,1.83,1.63,1.27,1}), E40<>"", LOOKUP(_xlfn.XLOOKUP(D40, Move_List!$A:$A, Move_List!$D:$D), {0,60,80,90,100,110,120,150}, {2.5,2,2,1.94,1.8,1.68,1.58,1.33}), TRUE, 0 ) * IF(_xlfn.XLOOKUP(D40, Move_List!$A:$A, Move_List!$C:$C)="Physical", K40, I40), 0)} -> 0 | P40: =(J40 + L40 + M40) / 3 -> 103.66667 | Q40: =IF(O40>0, (N40+O40)/2, N40) * (P40 / 100) -> 10636.2 | R40: {=IFERROR(Q40 / IF(OR(_xlfn.IFNA(_xlfn.XLOOKUP(E40, Move_List!$A:$A, Move_List!$C:$C), "")={"Dynamax","Mega"}), G40*1.2, G40), 0)} -> 85.775806
...

Sheet StardustV1 (Sub100)
A1: Number | B1: Pokemon | C1: Move Type | D1: PE | E1: Spd | F1: Move Power | G1: Damage type | H1: Attack Stat | I1: Accuracy | J1: Resistances | K1: Damage | L1: PE Efficiency | M1: Strong Against | N1: 6★Preys | O1: 5★ Preys | P1: Notes
A2: 62 | B2: Vikavolt | C2: Bug | D2: 88 | E2: 35 | F2: 90 | G2: Special | H2: 113 | I2: 1 | J2: Fighting, Steel, Electric, Grass | K2: =F2*H2 -> 10170 | L2: =K2/D2 -> 115.56818 | M2: #REF! | N2: =IFERROR(__xludf.DUMMYFUNCTION("TEXTJOIN("", "", TRUE, FILTER(PokemonList!$C:$C, (PokemonList!$B:$B=""6★"") * (BYROW(PokemonList!$D:$D, LAMBDA(row, OR(INDEX(ISNUMBER(SEARCH(SPLIT(row, ""/""), M2)))))))))"),"#N/A") -> #N/A | O2: =IFERROR(__xludf.DUMMYFUNCTION("TEXTJOIN("", "", TRUE, FILTER(PokemonList!$C:$C, (PokemonList!$B:$B=""5★"") * (BYROW(PokemonList!$D:$D, LAMBDA(row, OR(INDEX(ISNUMBER(SEARCH(SPLIT(row, ""/""), M2)))))))))"),"#N/A") -> #N/A | P2: Highest Damage
A3: 45 | B3: Jolteon | C3: Electric | D3: 90 | E3: 99 | F3: 110 | G3: Special | H3: 84 | I3: 0.7 | J3: Flying, Steel, Electric | K3: =F3*H3 -> 9240 | L3: =K3/D3 -> 102.66667 | M3: #REF! | N3: =IFERROR(__xludf.DUMMYFUNCTION("TEXTJOIN("", "", TRUE, FILTER(PokemonList!$C:$C, (PokemonList!$B:$B=""6★"") * (BYROW(PokemonList!$D:$D, LAMBDA(row, OR(INDEX(ISNUMBER(SEARCH(SPLIT(row, ""/""), M3)))))))))"),"#N/A") -> #N/A | O3: =IFERROR(__xludf.DUMMYFUNCTION("TEXTJOIN("", "", TRUE, FILTER(PokemonList!$C:$C, (PokemonList!$B:$B=""5★"") * (BYROW(PokemonList!$D:$D, LAMBDA(row, OR(INDEX(ISNUMBER(SEARCH(SPLIT(row, ""/""), M3)))))))))"),"#N/A") -> #N/A
A4: 43 | B4: Raichu | C4: Electric | D4: 84 | E4: 84 | F4: 110 | G4: Special | H4: 69 | I4: 0.7 | J4: Flying, Steel, Electric | K4: =F4*H4 -> 7590 | L4: =K4/D4 -> 90.357143 | M4: #REF! | N4: =IFERROR(__xludf.DUMMYFUNCTION("TEXTJOIN("", "", TRUE, FILTER(PokemonList!$C:$C, (PokemonList!$B:$B=""6★"") * (BYROW(PokemonList!$D:$D, LAMBDA(row, OR(INDEX(ISNUMBER(SEARCH(SPLIT(row, ""/""), M4)))))))))"),"#N/A") -> #N/A | O4: =IFERROR(__xludf.DUMMYFUNCTION("TEXTJOIN("", "", TRUE, FILTER(PokemonList!$C:$C, (PokemonList!$B:$B=""5★"") * (BYROW(PokemonList!$D:$D, LAMBDA(row, OR(INDEX(ISNUMBER(SEARCH(SPLIT(row, ""/""), M4)))))))))"),"#N/A") -> #N/A
A5: 56 | B5: Mudsdale | C5: Ground | D5: 90 | E5: 31 | F5: 75 | G5: Physical | H5: 100 | I5: 1 | J5: Poison, Rock, Electric | K5: =F5*H5 -> 7500 | L5: =K5/D5 -> 83.333333 | M5: #REF! | N5: =IFERROR(__xludf.DUMMYFUNCTION("TEXTJOIN("", "", TRUE, FILTER(PokemonList!$C:$C, (PokemonList!$B:$B=""6★"") * (BYROW(PokemonList!$D:$D, LAMBDA(row, OR(INDEX(ISNUMBER(SEARCH(SPLIT(row, ""/""), M5)))))))))"),"#N/A") -> #N/A | O5: =IFERROR(__xludf.DUMMYFUNCTION("TEXTJOIN("", "", TRUE, FILTER(PokemonList!$C:$C, (PokemonList!$B:$B=""5★"") * (BYROW(PokemonList!$D:$D, LAMBDA(row, OR(INDEX(ISNUMBER(SEARCH(SPLIT(row, ""/""), M5)))))))))"),"#N/A") -> #N/A
A6: 37 | B6: Cinderace | C6: Fire | D6: 90 | E6: 90 | F6: 85 | G6: Physical | H6: 88 | I6: 0.9 | J6: Bug, Steel, Fire, Grass, Ice, Fairy | K6: =F6*H6 -> 7480 | L6: =K6/D6 -> 83.111111 | M6: #REF! | N6: =IFERROR(__xludf.DUMMYFUNCTION("TEXTJOIN("", "", TRUE, FILTER(PokemonList!$C:$C, (PokemonList!$B:$B=""6★"") * (BYROW(PokemonList!$D:$D, LAMBDA(row, OR(INDEX(ISNUMBER(SEARCH(SPLIT(row, ""/""), M6)))))))))"),"#N/A") -> #N/A | O6: =IFERROR(__xludf.DUMMYFUNCTION("TEXTJOIN("", "", TRUE, FILTER(PokemonList!$C:$C, (PokemonList!$B:$B=""5★"") * (BYROW(PokemonList!$D:$D, LAMBDA(row, OR(INDEX(ISNUMBER(SEARCH(SPLIT(row, ""/""), M6)))))))))"),"#N/A") -> #N/A
A7: 34 | B7: Rillaboom | C7: Grass | D7: 90 | E7: 66 | F7: 77.5 | G7: Physical | H7: 95 | I7: 1 | J7: Ground, Water, Electric, Grass | K7: =F7*H7 -> 7362.5 | L7: =K7/D7 -> 81.805556 | M7: #REF! | N7: =IFERROR(__xludf.DUMMYFUNCTION("TEXTJOIN("", "", TRUE, FILTER(PokemonList!$C:$C, (PokemonList!$B:$B=""6★"") * (BYROW(PokemonList!$D:$D, LAMBDA(row, OR(INDEX(ISNUMBER(SEARCH(SPLIT(row, ""/""), M7)))))))))"),"#N/A") -> #N/A | O7: =IFERROR(__xludf.DUMMYFUNCTION("TEXTJOIN("", "", TRUE, FILTER(PokemonList!$C:$C, (PokemonList!$B:$B=""5★"") * (BYROW(PokemonList!$D:$D, LAMBDA(row, OR(INDEX(ISNUMBER(SEARCH(SPLIT(row, ""/""), M7)))))))))"),"#N/A") -> #N/A
A8: 70 | B8: Frosmoth | C8: Ice | D8: 86 | E8: 54 | F8: 65 | G8: Special | H8: 100 | I8: 1 | J8: Ground, Grass, Ice | K8: =F8*H8 -> 6500 | L8: =K8/D8 -> 75.581395 | M8: #REF! | N8: =IFERROR(__xludf.DUMMYFUNCTION("TEXTJOIN("", "", TRUE, FILTER(PokemonList!$C:$C, (PokemonList!$B:$B=""6★"") * (BYROW(PokemonList!$D:$D, LAMBDA(row, OR(INDEX(ISNUMBER(SEARCH(SPLIT(row, ""/""), M8)))))))))"),"#N/A") -> #N/A | O8: =IFERROR(__xludf.DUMMYFUNCTION("TEXTJOIN("", "", TRUE, FILTER(PokemonList!$C:$C, (PokemonList!$B:$B=""5★"") * (BYROW(PokemonList!$D:$D, LAMBDA(row, OR(INDEX(ISNUMBER(SEARCH(SPLIT(row, ""/""), M8)))))))))"),"#N/A") -> #N/A
A9: 48 | B9: Sylveon | C9: Fairy | D9: 96 | E9: 51 | F9: 80 | G9: Special | H9: 90 | I9: 1 | J9: Fighting, Bug, Dark | K9: =F9*H9 -> 7200 | L9: =K9/D9 -> 75 | M9: #REF! | N9: =IFERROR(__xludf.DUMMYFUNCTION("TEXTJOIN("", "", TRUE, FILTER(PokemonList!$C:$C, (PokemonList!$B:$B=""6★"") * (BYROW(PokemonList!$D:$D, LAMBDA(row, OR(INDEX(ISNUMBER(SEARCH(SPLIT(row, ""/""), M9)))))))))"),"#N/A") -> #N/A | O9: =IFERROR(__xludf.DUMMYFUNCTION("TEXTJOIN("", "", TRUE, FILTER(PokemonList!$C:$C, (PokemonList!$B:$B=""5★"") * (BYROW(PokemonList!$D:$D, LAMBDA(row, OR(INDEX(ISNUMBER(SEARCH(SPLIT(row, ""/""), M9)))))))))"),"#N/A") -> #N/A
